<?xml version="1.0"?>
<robot name="myarm"  xmlns:xacro="http://www.ros.org/wiki/xacro">

<!-- define the colors used in this robot -->
<material name="yellow">
	<color rgba="1 0.4 0 1"/>
</material>
<material name="black">
	<color rgba="0 0 0 0.95"/>
</material>
<material name="gray">
	<color rgba="0.75 0.75 0.75 1"/>
</material>

<xacro:macro name="arm">
 <link
    name="base_link">
    <inertial>
      <origin
        xyz="0.27085 -0.053615 -0.26586"
        rpy="0 0 0" />
      <mass
        value="0.354" />
      <inertia
        ixx="0.00060153"
        ixy="2.9029E-06"
        ixz="-2.7643E-07"
        iyy="0.0010552"
        iyz="1.3951E-06"
        izz="0.00059939" />
    </inertial>
    <visual>
      <origin
        xyz="0 0 0"
        rpy="0 0 0" />
      <geometry>
        <mesh
          filename="package://myarm/meshes/base_link.STL" />
      </geometry>
      <material
        name="gray">
      </material>
    </visual>
    <collision>
      <origin
        xyz="0 0 0"
        rpy="0 0 0" />
      <geometry>
        <mesh
          filename="package://myarm/meshes/base_link.STL" />
      </geometry>
    </collision>
  </link>
  <link
    name="Link0">
    <inertial>
      <origin
        xyz="0.0028026 0.013893 -1.2684E-06"
        rpy="0 0 0" />
      <mass
        value="0.045443" />
      <inertia
        ixx="1.6117E-05"
        ixy="-2.2584E-06"
        ixz="-4.8228E-11"
        iyy="1.3983E-05"
        iyz="8.439E-10"
        izz="1.439E-05" />
    </inertial>
    <visual>
      <origin
        xyz="0 0 0"
        rpy="0 0 0" />
      <geometry>
        <mesh
          filename="package://myarm/meshes/Link0.STL" />
      </geometry>
      <material
        name="gray">
      </material>
    </visual>
    <collision>
      <origin
        xyz="0 0 0"
        rpy="0 0 0" />
      <geometry>
        <mesh
          filename="package://myarm/meshes/Link0.STL" />
      </geometry>
    </collision>
  </link>
  <joint
    name="joint0"
    type="revolute">
    <origin
      xyz="0.27135 0.26556 -0.023642"
      rpy="1.5708 1.6316E-17 2.872" />
    <parent
      link="base_link" />
    <child
      link="Link0" />
    <axis
      xyz="0 1 0" />
    <limit
      lower="-2.36"
      upper="2.36"
      effort="0"
      velocity="0" />
  </joint>
  <link
    name="Link1">
    <inertial>
      <origin
        xyz="-1.8999E-09 0.038517 0.023376"
        rpy="0 0 0" />
      <mass
        value="0.059624" />
      <inertia
        ixx="5.7861E-05"
        ixy="-2.4536E-11"
        ixz="-1.5929E-12"
        iyy="2.9224E-05"
        iyz="4.6677E-06"
        izz="4.8415E-05" />
    </inertial>
    <visual>
      <origin
        xyz="0 0 0"
        rpy="0 0 0" />
      <geometry>
        <mesh
          filename="package://myarm/meshes/Link1.STL" />
      </geometry>
      <material
        name="gray">
      </material>
    </visual>
    <collision>
      <origin
        xyz="0 0 0"
        rpy="0 0 0" />
      <geometry>
        <mesh
          filename="package://myarm/meshes/Link1.STL" />
      </geometry>
    </collision>
  </link>
  <joint
    name="joint1"
    type="revolute">
    <origin
      xyz="0.0254 0.0365 0"
      rpy="-1.5708 -1.5136 1.5708" />
    <parent
      link="Link0" />
    <child
      link="Link1" />
    <axis
      xyz="0 0 1" />
    <limit
      lower="-2.36"
      upper="2.36"
      effort="0"
      velocity="0" />
  </joint>
  <link
    name="Link2">
    <inertial>
      <origin
        xyz="-1.5797E-09 0.038517 0.023376"
        rpy="0 0 0" />
      <mass
        value="0.059624" />
      <inertia
        ixx="5.7861E-05"
        ixy="-2.47E-11"
        ixz="-1.6726E-12"
        iyy="2.9224E-05"
        iyz="4.6677E-06"
        izz="4.8415E-05" />
    </inertial>
    <visual>
      <origin
        xyz="0 0 0"
        rpy="0 0 0" />
      <geometry>
        <mesh
          filename="package://myarm/meshes/Link2.STL" />
      </geometry>
      <material
        name="gray">
      </material>
    </visual>
    <collision>
      <origin
        xyz="0 0 0"
        rpy="0 0 0" />
      <geometry>
        <mesh
          filename="package://myarm/meshes/Link2.STL" />
      </geometry>
    </collision>
  </link>
  <joint
    name="joint2"
    type="revolute">
    <origin
      xyz="0 0.0745 -0.0004"
      rpy="2.3107E-15 5.5511E-17 0.010465" />
    <parent
      link="Link1" />
    <child
      link="Link2" />
    <axis
      xyz="0 0 1" />
    <limit
      lower="-2.36"
      upper="2.36"
      effort="0"
      velocity="0" />
  </joint>
  <link
    name="Link3">
    <inertial>
      <origin
        xyz="-1.2897E-08 0.038517 0.023376"
        rpy="0 0 0" />
      <mass
        value="0.059624" />
      <inertia
        ixx="5.7861E-05"
        ixy="-3.4206E-11"
        ixz="-1.1624E-11"
        iyy="2.9224E-05"
        iyz="4.6677E-06"
        izz="4.8415E-05" />
    </inertial>
    <visual>
      <origin
        xyz="0 0 0"
        rpy="0 0 0" />
      <geometry>
        <mesh
          filename="package://myarm/meshes/Link3.STL" />
      </geometry>
      <material
        name="gray">
      </material>
    </visual>
    <collision>
      <origin
        xyz="0 0 0"
        rpy="0 0 0" />
      <geometry>
        <mesh
          filename="package://myarm/meshes/Link3.STL" />
      </geometry>
    </collision>
  </link>
  <joint
    name="joint3"
    type="revolute">
    <origin
      xyz="0 0.0745 -0.0004"
      rpy="-4.9266E-16 -1.6653E-16 0.011929" />
    <parent
      link="Link2" />
    <child
      link="Link3" />
    <axis
      xyz="0 0 1" />
    <limit
      lower="-2.36"
      upper="2.36"
      effort="0"
      velocity="0" />
  </joint>
  <link
    name="Link4">
    <inertial>
      <origin
        xyz="-0.00019736 0.02219 0.027134"
        rpy="0 0 0" />
      <mass
        value="0.041798" />
      <inertia
        ixx="3.3475E-05"
        ixy="9.0738E-08"
        ixz="-1.106E-09"
        iyy="2.3209E-05"
        iyz="1.5196E-07"
        izz="1.9479E-05" />
    </inertial>
    <visual>
      <origin
        xyz="0 0 0"
        rpy="0 0 0" />
      <geometry>
        <mesh
          filename="package://myarm/meshes/Link4.STL" />
      </geometry>
      <material
        name="gray">
      </material>
    </visual>
    <collision>
      <origin
        xyz="0 0 0"
        rpy="0 0 0" />
      <geometry>
        <mesh
          filename="package://myarm/meshes/Link4.STL" />
      </geometry>
    </collision>
  </link>
  <joint
    name="joint4"
    type="revolute">
    <origin
      xyz="0 0.0745 -0.0014"
      rpy="-4.3819E-15 -2.7756E-16 -0.047644" />
    <parent
      link="Link3" />
    <child
      link="Link4" />
    <axis
      xyz="0 0 1" />
    <limit
      lower="-2.36"
      upper="2.36"
      effort="0"
      velocity="0" />
  </joint>
</xacro:macro>

</robot>
